django.request ERROR 2023-05-28 09:34:22,758 log 1081 140415499962112 Internal Server Error: /orders/new/
Traceback (most recent call last):
  File "/mnt/d/GithubApps/django_allauth/uvenv/lib/python3.8/site-packages/django/template/base.py", line 505, in parse
    compile_func = self.tags[command]
KeyError: 'endblock'

During handling of the above exception, another exception occurred:

Traceback (most recent call last):
  File "/mnt/d/GithubApps/django_allauth/uvenv/lib/python3.8/site-packages/django/core/handlers/exception.py", line 56, in inner
    response = get_response(request)
  File "/mnt/d/GithubApps/django_allauth/uvenv/lib/python3.8/site-packages/django/core/handlers/base.py", line 197, in _get_response
    response = wrapped_callback(request, *callback_args, **callback_kwargs)
  File "/mnt/d/GithubApps/django_allauth/uvenv/lib/python3.8/site-packages/django/contrib/auth/decorators.py", line 23, in _wrapped_view
    return view_func(request, *args, **kwargs)
  File "/mnt/d/GithubApps/django_allauth/businesscard/views.py", line 356, in NewBusinessRequest
    return render(request, 'businesscard/NewBusinessRequest.html', context)
  File "/mnt/d/GithubApps/django_allauth/uvenv/lib/python3.8/site-packages/django/shortcuts.py", line 24, in render
    content = loader.render_to_string(template_name, context, request, using=using)
  File "/mnt/d/GithubApps/django_allauth/uvenv/lib/python3.8/site-packages/django/template/loader.py", line 61, in render_to_string
    template = get_template(template_name, using=using)
  File "/mnt/d/GithubApps/django_allauth/uvenv/lib/python3.8/site-packages/django/template/loader.py", line 15, in get_template
    return engine.get_template(template_name)
  File "/mnt/d/GithubApps/django_allauth/uvenv/lib/python3.8/site-packages/django/template/backends/django.py", line 33, in get_template
    return Template(self.engine.get_template(template_name), self)
  File "/mnt/d/GithubApps/django_allauth/uvenv/lib/python3.8/site-packages/django/template/engine.py", line 175, in get_template
    template, origin = self.find_template(template_name)
  File "/mnt/d/GithubApps/django_allauth/uvenv/lib/python3.8/site-packages/django/template/engine.py", line 157, in find_template
    template = loader.get_template(name, skip=skip)
  File "/mnt/d/GithubApps/django_allauth/uvenv/lib/python3.8/site-packages/django/template/loaders/cached.py", line 57, in get_template
    template = super().get_template(template_name, skip)
  File "/mnt/d/GithubApps/django_allauth/uvenv/lib/python3.8/site-packages/django/template/loaders/base.py", line 28, in get_template
    return Template(
  File "/mnt/d/GithubApps/django_allauth/uvenv/lib/python3.8/site-packages/django/template/base.py", line 154, in __init__
    self.nodelist = self.compile_nodelist()
  File "/mnt/d/GithubApps/django_allauth/uvenv/lib/python3.8/site-packages/django/template/base.py", line 200, in compile_nodelist
    return parser.parse()
  File "/mnt/d/GithubApps/django_allauth/uvenv/lib/python3.8/site-packages/django/template/base.py", line 513, in parse
    raise self.error(token, e)
  File "/mnt/d/GithubApps/django_allauth/uvenv/lib/python3.8/site-packages/django/template/base.py", line 511, in parse
    compiled_result = compile_func(self, token)
  File "/mnt/d/GithubApps/django_allauth/uvenv/lib/python3.8/site-packages/django/template/loader_tags.py", line 293, in do_extends
    nodelist = parser.parse()
  File "/mnt/d/GithubApps/django_allauth/uvenv/lib/python3.8/site-packages/django/template/base.py", line 513, in parse
    raise self.error(token, e)
  File "/mnt/d/GithubApps/django_allauth/uvenv/lib/python3.8/site-packages/django/template/base.py", line 511, in parse
    compiled_result = compile_func(self, token)
  File "/mnt/d/GithubApps/django_allauth/uvenv/lib/python3.8/site-packages/django/template/loader_tags.py", line 232, in do_block
    nodelist = parser.parse(("endblock",))
  File "/mnt/d/GithubApps/django_allauth/uvenv/lib/python3.8/site-packages/django/template/base.py", line 513, in parse
    raise self.error(token, e)
  File "/mnt/d/GithubApps/django_allauth/uvenv/lib/python3.8/site-packages/django/template/base.py", line 511, in parse
    compiled_result = compile_func(self, token)
  File "/mnt/d/GithubApps/django_allauth/uvenv/lib/python3.8/site-packages/django/template/defaulttags.py", line 953, in do_if
    nodelist = parser.parse(("elif", "else", "endif"))
  File "/mnt/d/GithubApps/django_allauth/uvenv/lib/python3.8/site-packages/django/template/base.py", line 507, in parse
    self.invalid_block_tag(token, command, parse_until)
  File "/mnt/d/GithubApps/django_allauth/uvenv/lib/python3.8/site-packages/django/template/base.py", line 558, in invalid_block_tag
    raise self.error(
django.template.exceptions.TemplateSyntaxError: Invalid block tag on line 417: 'endblock', expected 'elif', 'else' or 'endif'. Did you forget to register or load this tag?
django.server ERROR 2023-05-28 09:34:22,778 basehttp 1081 140415499962112 "GET /orders/new/ HTTP/1.1" 500 261324
django.request ERROR 2023-05-28 09:40:27,533 log 1081 140415499962112 Internal Server Error: /orders/new/
Traceback (most recent call last):
  File "/mnt/d/GithubApps/django_allauth/uvenv/lib/python3.8/site-packages/django/core/handlers/exception.py", line 56, in inner
    response = get_response(request)
  File "/mnt/d/GithubApps/django_allauth/uvenv/lib/python3.8/site-packages/django/core/handlers/base.py", line 197, in _get_response
    response = wrapped_callback(request, *callback_args, **callback_kwargs)
  File "/mnt/d/GithubApps/django_allauth/uvenv/lib/python3.8/site-packages/django/contrib/auth/decorators.py", line 23, in _wrapped_view
    return view_func(request, *args, **kwargs)
  File "/mnt/d/GithubApps/django_allauth/businesscard/views.py", line 292, in NewBusinessRequest
    BusinessRequestFormResult.save()
  File "/mnt/d/GithubApps/django_allauth/uvenv/lib/python3.8/site-packages/django/db/models/base.py", line 812, in save
    self.save_base(
  File "/mnt/d/GithubApps/django_allauth/uvenv/lib/python3.8/site-packages/django/db/models/base.py", line 878, in save_base
    post_save.send(
  File "/mnt/d/GithubApps/django_allauth/uvenv/lib/python3.8/site-packages/django/dispatch/dispatcher.py", line 176, in send
    return [
  File "/mnt/d/GithubApps/django_allauth/uvenv/lib/python3.8/site-packages/django/dispatch/dispatcher.py", line 177, in <listcomp>
    (receiver, receiver(signal=self, sender=sender, **named))
  File "/mnt/d/GithubApps/django_allauth/businesscard/models.py", line 76, in BusinessRequest_send_email
    instance.generate_pdf()
AttributeError: 'BusinessRequest' object has no attribute 'generate_pdf'
django.server ERROR 2023-05-28 09:40:27,548 basehttp 1081 140415499962112 "POST /orders/new/ HTTP/1.1" 500 107425
